[2025-04-15T17:31:59.454+0200] {local_task_job_runner.py:123} INFO - ::group::Pre task execution logs
[2025-04-15T17:31:59.454+0200] {local_task_job_runner.py:123} INFO - ::group::Pre task execution logs
[2025-04-15T17:31:59.475+0200] {taskinstance.py:2614} INFO - Dependencies all met for dep_context=non-requeueable deps ti=<TaskInstance: dbt_snowflake_pipeline.dbt_tasks.dbt_debug manual__2025-04-15T15:31:51.247836+00:00 [queued]>
[2025-04-15T17:31:59.476+0200] {taskinstance.py:2614} INFO - Dependencies all met for dep_context=non-requeueable deps ti=<TaskInstance: dbt_snowflake_pipeline.dbt_tasks.dbt_debug manual__2025-04-15T15:31:51.247836+00:00 [queued]>
[2025-04-15T17:31:59.485+0200] {taskinstance.py:2614} INFO - Dependencies all met for dep_context=requeueable deps ti=<TaskInstance: dbt_snowflake_pipeline.dbt_tasks.dbt_debug manual__2025-04-15T15:31:51.247836+00:00 [queued]>
[2025-04-15T17:31:59.485+0200] {taskinstance.py:2867} INFO - Starting attempt 1 of 2
[2025-04-15T17:31:59.485+0200] {taskinstance.py:2614} INFO - Dependencies all met for dep_context=requeueable deps ti=<TaskInstance: dbt_snowflake_pipeline.dbt_tasks.dbt_debug manual__2025-04-15T15:31:51.247836+00:00 [queued]>
[2025-04-15T17:31:59.486+0200] {taskinstance.py:2867} INFO - Starting attempt 1 of 2
[2025-04-15T17:31:59.498+0200] {taskinstance.py:2890} INFO - Executing <Task(BashOperator): dbt_tasks.dbt_debug> on 2025-04-15 15:31:51.247836+00:00
[2025-04-15T17:31:59.503+0200] {taskinstance.py:2890} INFO - Executing <Task(BashOperator): dbt_tasks.dbt_debug> on 2025-04-15 15:31:51.247836+00:00
[2025-04-15T17:31:59.504+0200] {standard_task_runner.py:72} INFO - Started process 62680 to run task
[2025-04-15T17:31:59.510+0200] {standard_task_runner.py:72} INFO - Started process 62681 to run task
[2025-04-15T17:31:59.514+0200] {standard_task_runner.py:104} INFO - Running: ['airflow', 'tasks', 'run', 'dbt_snowflake_pipeline', 'dbt_tasks.dbt_debug', 'manual__2025-04-15T15:31:51.247836+00:00', '--job-id', '19', '--raw', '--subdir', 'DAGS_FOLDER/dbt_snowflke_airflow.py', '--cfg-path', '/var/folders/gn/cr4yj18d1tv34pkws9v_kq1r0000gn/T/tmpvq7o0pt5']
[2025-04-15T17:31:59.517+0200] {standard_task_runner.py:105} INFO - Job 19: Subtask dbt_tasks.dbt_debug
[2025-04-15T17:31:59.520+0200] {standard_task_runner.py:104} INFO - Running: ['airflow', 'tasks', 'run', 'dbt_snowflake_pipeline', 'dbt_tasks.dbt_debug', 'manual__2025-04-15T15:31:51.247836+00:00', '--job-id', '20', '--raw', '--subdir', 'DAGS_FOLDER/dbt_snowflke_airflow.py', '--cfg-path', '/var/folders/gn/cr4yj18d1tv34pkws9v_kq1r0000gn/T/tmpsaxraiuf']
[2025-04-15T17:31:59.524+0200] {standard_task_runner.py:105} INFO - Job 20: Subtask dbt_tasks.dbt_debug
[2025-04-15T17:31:59.579+0200] {task_command.py:467} INFO - Running <TaskInstance: dbt_snowflake_pipeline.dbt_tasks.dbt_debug manual__2025-04-15T15:31:51.247836+00:00 [running]> on host macbook-pro-de-user.local
[2025-04-15T17:31:59.582+0200] {task_command.py:467} INFO - Running <TaskInstance: dbt_snowflake_pipeline.dbt_tasks.dbt_debug manual__2025-04-15T15:31:51.247836+00:00 [running]> on host macbook-pro-de-user.local
[2025-04-15T17:31:59.643+0200] {taskinstance.py:3134} INFO - Exporting env vars: AIRFLOW_CTX_DAG_OWNER='airflow' AIRFLOW_CTX_DAG_ID='dbt_snowflake_pipeline' AIRFLOW_CTX_TASK_ID='dbt_tasks.dbt_debug' AIRFLOW_CTX_EXECUTION_DATE='2025-04-15T15:31:51.247836+00:00' AIRFLOW_CTX_TRY_NUMBER='1' AIRFLOW_CTX_DAG_RUN_ID='manual__2025-04-15T15:31:51.247836+00:00'
[2025-04-15T17:31:59.645+0200] {logging_mixin.py:190} INFO - Task instance is in running state
[2025-04-15T17:31:59.646+0200] {logging_mixin.py:190} INFO -  Previous state of the Task instance: queued
[2025-04-15T17:31:59.647+0200] {logging_mixin.py:190} INFO - Current task name:dbt_tasks.dbt_debug state:running start_date:2025-04-15 15:31:59.476528+00:00
[2025-04-15T17:31:59.647+0200] {logging_mixin.py:190} INFO - Dag name:dbt_snowflake_pipeline and current dag run status:running
[2025-04-15T17:31:59.648+0200] {taskinstance.py:732} INFO - ::endgroup::
[2025-04-15T17:31:59.649+0200] {subprocess.py:78} INFO - Tmp dir root location: /var/folders/gn/cr4yj18d1tv34pkws9v_kq1r0000gn/T
[2025-04-15T17:31:59.651+0200] {subprocess.py:88} INFO - Running command: ['/bin/bash', '-c', 'dbt debug --profiles-dir ~/.dbt/profiles.yml --project-dir /Users/user/Documents/learningProg/dataengineering/de_dbt_snowflake_airflow/snowflake']
[2025-04-15T17:31:59.658+0200] {subprocess.py:99} INFO - Output:
[2025-04-15T17:31:59.645+0200] {taskinstance.py:3313} ERROR - Task failed with exception
Traceback (most recent call last):
  File "/Users/user/Documents/learningProg/dataengineering/de_dbt_snowflake_airflow/airflow-env/lib/python3.11/site-packages/sqlalchemy/engine/base.py", line 1910, in _execute_context
    self.dialect.do_execute(
  File "/Users/user/Documents/learningProg/dataengineering/de_dbt_snowflake_airflow/airflow-env/lib/python3.11/site-packages/sqlalchemy/engine/default.py", line 736, in do_execute
    cursor.execute(statement, parameters)
sqlite3.IntegrityError: UNIQUE constraint failed: rendered_task_instance_fields.dag_id, rendered_task_instance_fields.task_id, rendered_task_instance_fields.run_id, rendered_task_instance_fields.map_index

The above exception was the direct cause of the following exception:

Traceback (most recent call last):
  File "/Users/user/Documents/learningProg/dataengineering/de_dbt_snowflake_airflow/airflow-env/lib/python3.11/site-packages/airflow/models/taskinstance.py", line 274, in _run_raw_task
    TaskInstance._execute_task_with_callbacks(
  File "/Users/user/Documents/learningProg/dataengineering/de_dbt_snowflake_airflow/airflow-env/lib/python3.11/site-packages/airflow/models/taskinstance.py", line 3125, in _execute_task_with_callbacks
    _update_rtif(ti=self, rendered_fields=rendered_fields)
  File "/Users/user/Documents/learningProg/dataengineering/de_dbt_snowflake_airflow/airflow-env/lib/python3.11/site-packages/airflow/api_internal/internal_api_call.py", line 166, in wrapper
    return func(*args, **kwargs)
           ^^^^^^^^^^^^^^^^^^^^^
  File "/Users/user/Documents/learningProg/dataengineering/de_dbt_snowflake_airflow/airflow-env/lib/python3.11/site-packages/airflow/utils/session.py", line 97, in wrapper
    return func(*args, session=session, **kwargs)
           ^^^^^^^^^^^^^^^^^^^^^^^^^^^^^^^^^^^^^^
  File "/Users/user/Documents/learningProg/dataengineering/de_dbt_snowflake_airflow/airflow-env/lib/python3.11/site-packages/airflow/models/taskinstance.py", line 1643, in _update_rtif
    session.flush()
  File "/Users/user/Documents/learningProg/dataengineering/de_dbt_snowflake_airflow/airflow-env/lib/python3.11/site-packages/sqlalchemy/orm/session.py", line 3449, in flush
    self._flush(objects)
  File "/Users/user/Documents/learningProg/dataengineering/de_dbt_snowflake_airflow/airflow-env/lib/python3.11/site-packages/sqlalchemy/orm/session.py", line 3588, in _flush
    with util.safe_reraise():
  File "/Users/user/Documents/learningProg/dataengineering/de_dbt_snowflake_airflow/airflow-env/lib/python3.11/site-packages/sqlalchemy/util/langhelpers.py", line 70, in __exit__
    compat.raise_(
  File "/Users/user/Documents/learningProg/dataengineering/de_dbt_snowflake_airflow/airflow-env/lib/python3.11/site-packages/sqlalchemy/util/compat.py", line 211, in raise_
    raise exception
  File "/Users/user/Documents/learningProg/dataengineering/de_dbt_snowflake_airflow/airflow-env/lib/python3.11/site-packages/sqlalchemy/orm/session.py", line 3549, in _flush
    flush_context.execute()
  File "/Users/user/Documents/learningProg/dataengineering/de_dbt_snowflake_airflow/airflow-env/lib/python3.11/site-packages/sqlalchemy/orm/unitofwork.py", line 456, in execute
    rec.execute(self)
  File "/Users/user/Documents/learningProg/dataengineering/de_dbt_snowflake_airflow/airflow-env/lib/python3.11/site-packages/sqlalchemy/orm/unitofwork.py", line 630, in execute
    util.preloaded.orm_persistence.save_obj(
  File "/Users/user/Documents/learningProg/dataengineering/de_dbt_snowflake_airflow/airflow-env/lib/python3.11/site-packages/sqlalchemy/orm/persistence.py", line 245, in save_obj
    _emit_insert_statements(
  File "/Users/user/Documents/learningProg/dataengineering/de_dbt_snowflake_airflow/airflow-env/lib/python3.11/site-packages/sqlalchemy/orm/persistence.py", line 1097, in _emit_insert_statements
    c = connection._execute_20(
        ^^^^^^^^^^^^^^^^^^^^^^^
  File "/Users/user/Documents/learningProg/dataengineering/de_dbt_snowflake_airflow/airflow-env/lib/python3.11/site-packages/sqlalchemy/engine/base.py", line 1710, in _execute_20
    return meth(self, args_10style, kwargs_10style, execution_options)
           ^^^^^^^^^^^^^^^^^^^^^^^^^^^^^^^^^^^^^^^^^^^^^^^^^^^^^^^^^^^
  File "/Users/user/Documents/learningProg/dataengineering/de_dbt_snowflake_airflow/airflow-env/lib/python3.11/site-packages/sqlalchemy/sql/elements.py", line 334, in _execute_on_connection
    return connection._execute_clauseelement(
           ^^^^^^^^^^^^^^^^^^^^^^^^^^^^^^^^^^
  File "/Users/user/Documents/learningProg/dataengineering/de_dbt_snowflake_airflow/airflow-env/lib/python3.11/site-packages/sqlalchemy/engine/base.py", line 1577, in _execute_clauseelement
    ret = self._execute_context(
          ^^^^^^^^^^^^^^^^^^^^^^
  File "/Users/user/Documents/learningProg/dataengineering/de_dbt_snowflake_airflow/airflow-env/lib/python3.11/site-packages/sqlalchemy/engine/base.py", line 1953, in _execute_context
    self._handle_dbapi_exception(
  File "/Users/user/Documents/learningProg/dataengineering/de_dbt_snowflake_airflow/airflow-env/lib/python3.11/site-packages/sqlalchemy/engine/base.py", line 2134, in _handle_dbapi_exception
    util.raise_(
  File "/Users/user/Documents/learningProg/dataengineering/de_dbt_snowflake_airflow/airflow-env/lib/python3.11/site-packages/sqlalchemy/util/compat.py", line 211, in raise_
    raise exception
  File "/Users/user/Documents/learningProg/dataengineering/de_dbt_snowflake_airflow/airflow-env/lib/python3.11/site-packages/sqlalchemy/engine/base.py", line 1910, in _execute_context
    self.dialect.do_execute(
  File "/Users/user/Documents/learningProg/dataengineering/de_dbt_snowflake_airflow/airflow-env/lib/python3.11/site-packages/sqlalchemy/engine/default.py", line 736, in do_execute
    cursor.execute(statement, parameters)
sqlalchemy.exc.IntegrityError: (sqlite3.IntegrityError) UNIQUE constraint failed: rendered_task_instance_fields.dag_id, rendered_task_instance_fields.task_id, rendered_task_instance_fields.run_id, rendered_task_instance_fields.map_index
[SQL: INSERT INTO rendered_task_instance_fields (dag_id, task_id, run_id, map_index, rendered_fields, k8s_pod_yaml) VALUES (?, ?, ?, ?, ?, ?)]
[parameters: ('dbt_snowflake_pipeline', 'dbt_tasks.dbt_debug', 'manual__2025-04-15T15:31:51.247836+00:00', -1, '{"bash_command": "dbt debug --profiles-dir ~/.dbt/profiles.yml --project-dir /Users/user/Documents/learningProg/dataengineering/de_dbt_snowflake_airflow/snowflake", "env": null, "cwd": null}', 'null')]
(Background on this error at: https://sqlalche.me/e/14/gkpj)
[2025-04-15T17:31:59.673+0200] {logging_mixin.py:190} INFO - Task instance in failure state
[2025-04-15T17:31:59.674+0200] {logging_mixin.py:190} INFO - Task start:2025-04-15 15:31:59.476528+00:00 end:2025-04-15 15:31:59.672362+00:00 duration:0.195834
[2025-04-15T17:31:59.675+0200] {logging_mixin.py:190} INFO - Task:<Task(BashOperator): dbt_tasks.dbt_debug> dag:<DAG: dbt_snowflake_pipeline> dagrun:<DagRun dbt_snowflake_pipeline @ 2025-04-15 15:31:51.247836+00:00: manual__2025-04-15T15:31:51.247836+00:00, state:running, queued_at: 2025-04-15 15:31:51.325711+00:00. externally triggered: True>
[2025-04-15T17:31:59.676+0200] {logging_mixin.py:190} INFO - Failure caused by (sqlite3.IntegrityError) UNIQUE constraint failed: rendered_task_instance_fields.dag_id, rendered_task_instance_fields.task_id, rendered_task_instance_fields.run_id, rendered_task_instance_fields.map_index
[SQL: INSERT INTO rendered_task_instance_fields (dag_id, task_id, run_id, map_index, rendered_fields, k8s_pod_yaml) VALUES (?, ?, ?, ?, ?, ?)]
[parameters: ('dbt_snowflake_pipeline', 'dbt_tasks.dbt_debug', 'manual__2025-04-15T15:31:51.247836+00:00', -1, '{"bash_command": "dbt debug --profiles-dir ~/.dbt/profiles.yml --project-dir /Users/user/Documents/learningProg/dataengineering/de_dbt_snowflake_airflow/snowflake", "env": null, "cwd": null}', 'null')]
(Background on this error at: https://sqlalche.me/e/14/gkpj)
[2025-04-15T17:31:59.678+0200] {taskinstance.py:1226} INFO - Marking task as UP_FOR_RETRY. dag_id=dbt_snowflake_pipeline, task_id=dbt_tasks.dbt_debug, run_id=manual__2025-04-15T15:31:51.247836+00:00, execution_date=20250415T153151, start_date=20250415T153159, end_date=20250415T153159
[2025-04-15T17:31:59.696+0200] {taskinstance.py:341} INFO - ::group::Post task execution logs
[2025-04-15T17:31:59.697+0200] {standard_task_runner.py:124} ERROR - Failed to execute job 20 for task dbt_tasks.dbt_debug ((sqlite3.IntegrityError) UNIQUE constraint failed: rendered_task_instance_fields.dag_id, rendered_task_instance_fields.task_id, rendered_task_instance_fields.run_id, rendered_task_instance_fields.map_index
[SQL: INSERT INTO rendered_task_instance_fields (dag_id, task_id, run_id, map_index, rendered_fields, k8s_pod_yaml) VALUES (?, ?, ?, ?, ?, ?)]
[parameters: ('dbt_snowflake_pipeline', 'dbt_tasks.dbt_debug', 'manual__2025-04-15T15:31:51.247836+00:00', -1, '{"bash_command": "dbt debug --profiles-dir ~/.dbt/profiles.yml --project-dir /Users/user/Documents/learningProg/dataengineering/de_dbt_snowflake_airflow/snowflake", "env": null, "cwd": null}', 'null')]
(Background on this error at: https://sqlalche.me/e/14/gkpj); 62681)
Traceback (most recent call last):
  File "/Users/user/Documents/learningProg/dataengineering/de_dbt_snowflake_airflow/airflow-env/lib/python3.11/site-packages/sqlalchemy/engine/base.py", line 1910, in _execute_context
    self.dialect.do_execute(
  File "/Users/user/Documents/learningProg/dataengineering/de_dbt_snowflake_airflow/airflow-env/lib/python3.11/site-packages/sqlalchemy/engine/default.py", line 736, in do_execute
    cursor.execute(statement, parameters)
sqlite3.IntegrityError: UNIQUE constraint failed: rendered_task_instance_fields.dag_id, rendered_task_instance_fields.task_id, rendered_task_instance_fields.run_id, rendered_task_instance_fields.map_index

The above exception was the direct cause of the following exception:

Traceback (most recent call last):
  File "/Users/user/Documents/learningProg/dataengineering/de_dbt_snowflake_airflow/airflow-env/lib/python3.11/site-packages/airflow/task/task_runner/standard_task_runner.py", line 117, in _start_by_fork
    ret = args.func(args, dag=self.dag)
          ^^^^^^^^^^^^^^^^^^^^^^^^^^^^^
  File "/Users/user/Documents/learningProg/dataengineering/de_dbt_snowflake_airflow/airflow-env/lib/python3.11/site-packages/airflow/cli/cli_config.py", line 49, in command
    return func(*args, **kwargs)
           ^^^^^^^^^^^^^^^^^^^^^
  File "/Users/user/Documents/learningProg/dataengineering/de_dbt_snowflake_airflow/airflow-env/lib/python3.11/site-packages/airflow/utils/cli.py", line 116, in wrapper
    return f(*args, **kwargs)
           ^^^^^^^^^^^^^^^^^^
  File "/Users/user/Documents/learningProg/dataengineering/de_dbt_snowflake_airflow/airflow-env/lib/python3.11/site-packages/airflow/cli/commands/task_command.py", line 483, in task_run
    task_return_code = _run_task_by_selected_method(args, _dag, ti)
                       ^^^^^^^^^^^^^^^^^^^^^^^^^^^^^^^^^^^^^^^^^^^^
  File "/Users/user/Documents/learningProg/dataengineering/de_dbt_snowflake_airflow/airflow-env/lib/python3.11/site-packages/airflow/cli/commands/task_command.py", line 256, in _run_task_by_selected_method
    return _run_raw_task(args, ti)
           ^^^^^^^^^^^^^^^^^^^^^^^
  File "/Users/user/Documents/learningProg/dataengineering/de_dbt_snowflake_airflow/airflow-env/lib/python3.11/site-packages/airflow/cli/commands/task_command.py", line 341, in _run_raw_task
    return ti._run_raw_task(
           ^^^^^^^^^^^^^^^^^
  File "/Users/user/Documents/learningProg/dataengineering/de_dbt_snowflake_airflow/airflow-env/lib/python3.11/site-packages/airflow/utils/session.py", line 97, in wrapper
    return func(*args, session=session, **kwargs)
           ^^^^^^^^^^^^^^^^^^^^^^^^^^^^^^^^^^^^^^
  File "/Users/user/Documents/learningProg/dataengineering/de_dbt_snowflake_airflow/airflow-env/lib/python3.11/site-packages/airflow/models/taskinstance.py", line 3006, in _run_raw_task
    return _run_raw_task(
           ^^^^^^^^^^^^^^
  File "/Users/user/Documents/learningProg/dataengineering/de_dbt_snowflake_airflow/airflow-env/lib/python3.11/site-packages/airflow/models/taskinstance.py", line 274, in _run_raw_task
    TaskInstance._execute_task_with_callbacks(
  File "/Users/user/Documents/learningProg/dataengineering/de_dbt_snowflake_airflow/airflow-env/lib/python3.11/site-packages/airflow/models/taskinstance.py", line 3125, in _execute_task_with_callbacks
    _update_rtif(ti=self, rendered_fields=rendered_fields)
  File "/Users/user/Documents/learningProg/dataengineering/de_dbt_snowflake_airflow/airflow-env/lib/python3.11/site-packages/airflow/api_internal/internal_api_call.py", line 166, in wrapper
    return func(*args, **kwargs)
           ^^^^^^^^^^^^^^^^^^^^^
  File "/Users/user/Documents/learningProg/dataengineering/de_dbt_snowflake_airflow/airflow-env/lib/python3.11/site-packages/airflow/utils/session.py", line 97, in wrapper
    return func(*args, session=session, **kwargs)
           ^^^^^^^^^^^^^^^^^^^^^^^^^^^^^^^^^^^^^^
  File "/Users/user/Documents/learningProg/dataengineering/de_dbt_snowflake_airflow/airflow-env/lib/python3.11/site-packages/airflow/models/taskinstance.py", line 1643, in _update_rtif
    session.flush()
  File "/Users/user/Documents/learningProg/dataengineering/de_dbt_snowflake_airflow/airflow-env/lib/python3.11/site-packages/sqlalchemy/orm/session.py", line 3449, in flush
    self._flush(objects)
  File "/Users/user/Documents/learningProg/dataengineering/de_dbt_snowflake_airflow/airflow-env/lib/python3.11/site-packages/sqlalchemy/orm/session.py", line 3588, in _flush
    with util.safe_reraise():
  File "/Users/user/Documents/learningProg/dataengineering/de_dbt_snowflake_airflow/airflow-env/lib/python3.11/site-packages/sqlalchemy/util/langhelpers.py", line 70, in __exit__
    compat.raise_(
  File "/Users/user/Documents/learningProg/dataengineering/de_dbt_snowflake_airflow/airflow-env/lib/python3.11/site-packages/sqlalchemy/util/compat.py", line 211, in raise_
    raise exception
  File "/Users/user/Documents/learningProg/dataengineering/de_dbt_snowflake_airflow/airflow-env/lib/python3.11/site-packages/sqlalchemy/orm/session.py", line 3549, in _flush
    flush_context.execute()
  File "/Users/user/Documents/learningProg/dataengineering/de_dbt_snowflake_airflow/airflow-env/lib/python3.11/site-packages/sqlalchemy/orm/unitofwork.py", line 456, in execute
    rec.execute(self)
  File "/Users/user/Documents/learningProg/dataengineering/de_dbt_snowflake_airflow/airflow-env/lib/python3.11/site-packages/sqlalchemy/orm/unitofwork.py", line 630, in execute
    util.preloaded.orm_persistence.save_obj(
  File "/Users/user/Documents/learningProg/dataengineering/de_dbt_snowflake_airflow/airflow-env/lib/python3.11/site-packages/sqlalchemy/orm/persistence.py", line 245, in save_obj
    _emit_insert_statements(
  File "/Users/user/Documents/learningProg/dataengineering/de_dbt_snowflake_airflow/airflow-env/lib/python3.11/site-packages/sqlalchemy/orm/persistence.py", line 1097, in _emit_insert_statements
    c = connection._execute_20(
        ^^^^^^^^^^^^^^^^^^^^^^^
  File "/Users/user/Documents/learningProg/dataengineering/de_dbt_snowflake_airflow/airflow-env/lib/python3.11/site-packages/sqlalchemy/engine/base.py", line 1710, in _execute_20
    return meth(self, args_10style, kwargs_10style, execution_options)
           ^^^^^^^^^^^^^^^^^^^^^^^^^^^^^^^^^^^^^^^^^^^^^^^^^^^^^^^^^^^
  File "/Users/user/Documents/learningProg/dataengineering/de_dbt_snowflake_airflow/airflow-env/lib/python3.11/site-packages/sqlalchemy/sql/elements.py", line 334, in _execute_on_connection
    return connection._execute_clauseelement(
           ^^^^^^^^^^^^^^^^^^^^^^^^^^^^^^^^^^
  File "/Users/user/Documents/learningProg/dataengineering/de_dbt_snowflake_airflow/airflow-env/lib/python3.11/site-packages/sqlalchemy/engine/base.py", line 1577, in _execute_clauseelement
    ret = self._execute_context(
          ^^^^^^^^^^^^^^^^^^^^^^
  File "/Users/user/Documents/learningProg/dataengineering/de_dbt_snowflake_airflow/airflow-env/lib/python3.11/site-packages/sqlalchemy/engine/base.py", line 1953, in _execute_context
    self._handle_dbapi_exception(
  File "/Users/user/Documents/learningProg/dataengineering/de_dbt_snowflake_airflow/airflow-env/lib/python3.11/site-packages/sqlalchemy/engine/base.py", line 2134, in _handle_dbapi_exception
    util.raise_(
  File "/Users/user/Documents/learningProg/dataengineering/de_dbt_snowflake_airflow/airflow-env/lib/python3.11/site-packages/sqlalchemy/util/compat.py", line 211, in raise_
    raise exception
  File "/Users/user/Documents/learningProg/dataengineering/de_dbt_snowflake_airflow/airflow-env/lib/python3.11/site-packages/sqlalchemy/engine/base.py", line 1910, in _execute_context
    self.dialect.do_execute(
  File "/Users/user/Documents/learningProg/dataengineering/de_dbt_snowflake_airflow/airflow-env/lib/python3.11/site-packages/sqlalchemy/engine/default.py", line 736, in do_execute
    cursor.execute(statement, parameters)
sqlalchemy.exc.IntegrityError: (sqlite3.IntegrityError) UNIQUE constraint failed: rendered_task_instance_fields.dag_id, rendered_task_instance_fields.task_id, rendered_task_instance_fields.run_id, rendered_task_instance_fields.map_index
[SQL: INSERT INTO rendered_task_instance_fields (dag_id, task_id, run_id, map_index, rendered_fields, k8s_pod_yaml) VALUES (?, ?, ?, ?, ?, ?)]
[parameters: ('dbt_snowflake_pipeline', 'dbt_tasks.dbt_debug', 'manual__2025-04-15T15:31:51.247836+00:00', -1, '{"bash_command": "dbt debug --profiles-dir ~/.dbt/profiles.yml --project-dir /Users/user/Documents/learningProg/dataengineering/de_dbt_snowflake_airflow/snowflake", "env": null, "cwd": null}', 'null')]
(Background on this error at: https://sqlalche.me/e/14/gkpj)
[2025-04-15T17:31:59.733+0200] {local_task_job_runner.py:266} INFO - Task exited with return code 1
[2025-04-15T17:31:59.759+0200] {taskinstance.py:3901} INFO - 0 downstream tasks scheduled from follow-on schedule check
[2025-04-15T17:31:59.760+0200] {local_task_job_runner.py:245} INFO - ::endgroup::
[2025-04-15T17:32:02.938+0200] {subprocess.py:106} INFO - [0m15:32:02  Running with dbt=1.9.4
[2025-04-15T17:32:02.974+0200] {subprocess.py:106} INFO - [0m15:32:02  dbt version: 1.9.4
[2025-04-15T17:32:02.976+0200] {subprocess.py:106} INFO - [0m15:32:02  python version: 3.11.11
[2025-04-15T17:32:02.976+0200] {subprocess.py:106} INFO - [0m15:32:02  python path: /Users/user/Documents/learningProg/dataengineering/de_dbt_snowflake_airflow/airflow-env/bin/python
[2025-04-15T17:32:02.977+0200] {subprocess.py:106} INFO - [0m15:32:02  os info: macOS-15.3.2-x86_64-i386-64bit
[2025-04-15T17:32:02.978+0200] {subprocess.py:106} INFO - [0m15:32:02  Using profiles dir at /Users/user/.dbt/profiles.yml
[2025-04-15T17:32:02.979+0200] {subprocess.py:106} INFO - [0m15:32:02  Using profiles.yml file at /Users/user/.dbt/profiles.yml/profiles.yml
[2025-04-15T17:32:02.980+0200] {subprocess.py:106} INFO - [0m15:32:02  Using dbt_project.yml file at /Users/user/Documents/learningProg/dataengineering/de_dbt_snowflake_airflow/snowflake/dbt_project.yml
[2025-04-15T17:32:03.195+0200] {subprocess.py:106} INFO - [0m15:32:03  Configuration:
[2025-04-15T17:32:03.196+0200] {subprocess.py:106} INFO - [0m15:32:03    profiles.yml file [[31mERROR not found[0m]
[2025-04-15T17:32:03.197+0200] {subprocess.py:106} INFO - [0m15:32:03    dbt_project.yml file [[32mOK found and valid[0m]
[2025-04-15T17:32:03.198+0200] {subprocess.py:106} INFO - [0m15:32:03  Required dependencies:
[2025-04-15T17:32:03.271+0200] {subprocess.py:106} INFO - [0m15:32:03   - git [[32mOK found[0m]
[2025-04-15T17:32:03.274+0200] {subprocess.py:106} INFO - 
[2025-04-15T17:32:03.276+0200] {subprocess.py:106} INFO - [0m15:32:03  Connection test skipped since no profile was found
[2025-04-15T17:32:03.277+0200] {subprocess.py:106} INFO - [0m15:32:03  [31m1 check failed:[0m
[2025-04-15T17:32:03.279+0200] {subprocess.py:106} INFO - [0m15:32:03  dbt looked for a profiles.yml file in /Users/user/.dbt/profiles.yml/profiles.yml, but did
[2025-04-15T17:32:03.282+0200] {subprocess.py:106} INFO - not find one. For more information on configuring your profile, consult the
[2025-04-15T17:32:03.284+0200] {subprocess.py:106} INFO - documentation:
[2025-04-15T17:32:03.285+0200] {subprocess.py:106} INFO - 
[2025-04-15T17:32:03.288+0200] {subprocess.py:106} INFO - https://docs.getdbt.com/docs/configure-your-profile
[2025-04-15T17:32:03.290+0200] {subprocess.py:106} INFO - 
[2025-04-15T17:32:03.291+0200] {subprocess.py:106} INFO - 
[2025-04-15T17:32:04.047+0200] {subprocess.py:110} INFO - Command exited with return code 1
[2025-04-15T17:32:04.074+0200] {taskinstance.py:3313} ERROR - Task failed with exception
Traceback (most recent call last):
  File "/Users/user/Documents/learningProg/dataengineering/de_dbt_snowflake_airflow/airflow-env/lib/python3.11/site-packages/airflow/models/taskinstance.py", line 768, in _execute_task
    result = _execute_callable(context=context, **execute_callable_kwargs)
             ^^^^^^^^^^^^^^^^^^^^^^^^^^^^^^^^^^^^^^^^^^^^^^^^^^^^^^^^^^^^^
  File "/Users/user/Documents/learningProg/dataengineering/de_dbt_snowflake_airflow/airflow-env/lib/python3.11/site-packages/airflow/models/taskinstance.py", line 734, in _execute_callable
    return ExecutionCallableRunner(
           ^^^^^^^^^^^^^^^^^^^^^^^^
  File "/Users/user/Documents/learningProg/dataengineering/de_dbt_snowflake_airflow/airflow-env/lib/python3.11/site-packages/airflow/utils/operator_helpers.py", line 252, in run
    return self.func(*args, **kwargs)
           ^^^^^^^^^^^^^^^^^^^^^^^^^^
  File "/Users/user/Documents/learningProg/dataengineering/de_dbt_snowflake_airflow/airflow-env/lib/python3.11/site-packages/airflow/models/baseoperator.py", line 424, in wrapper
    return func(self, *args, **kwargs)
           ^^^^^^^^^^^^^^^^^^^^^^^^^^^
  File "/Users/user/Documents/learningProg/dataengineering/de_dbt_snowflake_airflow/airflow-env/lib/python3.11/site-packages/airflow/operators/bash.py", line 276, in execute
    raise AirflowException(
airflow.exceptions.AirflowException: Bash command failed. The command returned a non-zero exit code 1.
[2025-04-15T17:32:04.087+0200] {logging_mixin.py:190} INFO - Task instance in failure state
[2025-04-15T17:32:04.088+0200] {logging_mixin.py:190} INFO - Task start:2025-04-15 15:31:59.476528+00:00 end:2025-04-15 15:32:04.085522+00:00 duration:4.608994
[2025-04-15T17:32:04.089+0200] {logging_mixin.py:190} INFO - Task:<Task(BashOperator): dbt_tasks.dbt_debug> dag:<DAG: dbt_snowflake_pipeline> dagrun:<DagRun dbt_snowflake_pipeline @ 2025-04-15 15:31:51.247836+00:00: manual__2025-04-15T15:31:51.247836+00:00, state:running, queued_at: 2025-04-15 15:31:51.325711+00:00. externally triggered: True>
[2025-04-15T17:32:04.090+0200] {logging_mixin.py:190} INFO - Failure caused by Bash command failed. The command returned a non-zero exit code 1.
[2025-04-15T17:32:04.092+0200] {taskinstance.py:1226} INFO - Marking task as UP_FOR_RETRY. dag_id=dbt_snowflake_pipeline, task_id=dbt_tasks.dbt_debug, run_id=manual__2025-04-15T15:31:51.247836+00:00, execution_date=20250415T153151, start_date=20250415T153159, end_date=20250415T153204
[2025-04-15T17:32:04.125+0200] {taskinstance.py:341} INFO - ::group::Post task execution logs
[2025-04-15T17:32:04.127+0200] {standard_task_runner.py:124} ERROR - Failed to execute job 19 for task dbt_tasks.dbt_debug (Bash command failed. The command returned a non-zero exit code 1.; 62680)
Traceback (most recent call last):
  File "/Users/user/Documents/learningProg/dataengineering/de_dbt_snowflake_airflow/airflow-env/lib/python3.11/site-packages/airflow/task/task_runner/standard_task_runner.py", line 117, in _start_by_fork
    ret = args.func(args, dag=self.dag)
          ^^^^^^^^^^^^^^^^^^^^^^^^^^^^^
  File "/Users/user/Documents/learningProg/dataengineering/de_dbt_snowflake_airflow/airflow-env/lib/python3.11/site-packages/airflow/cli/cli_config.py", line 49, in command
    return func(*args, **kwargs)
           ^^^^^^^^^^^^^^^^^^^^^
  File "/Users/user/Documents/learningProg/dataengineering/de_dbt_snowflake_airflow/airflow-env/lib/python3.11/site-packages/airflow/utils/cli.py", line 116, in wrapper
    return f(*args, **kwargs)
           ^^^^^^^^^^^^^^^^^^
  File "/Users/user/Documents/learningProg/dataengineering/de_dbt_snowflake_airflow/airflow-env/lib/python3.11/site-packages/airflow/cli/commands/task_command.py", line 483, in task_run
    task_return_code = _run_task_by_selected_method(args, _dag, ti)
                       ^^^^^^^^^^^^^^^^^^^^^^^^^^^^^^^^^^^^^^^^^^^^
  File "/Users/user/Documents/learningProg/dataengineering/de_dbt_snowflake_airflow/airflow-env/lib/python3.11/site-packages/airflow/cli/commands/task_command.py", line 256, in _run_task_by_selected_method
    return _run_raw_task(args, ti)
           ^^^^^^^^^^^^^^^^^^^^^^^
  File "/Users/user/Documents/learningProg/dataengineering/de_dbt_snowflake_airflow/airflow-env/lib/python3.11/site-packages/airflow/cli/commands/task_command.py", line 341, in _run_raw_task
    return ti._run_raw_task(
           ^^^^^^^^^^^^^^^^^
  File "/Users/user/Documents/learningProg/dataengineering/de_dbt_snowflake_airflow/airflow-env/lib/python3.11/site-packages/airflow/utils/session.py", line 97, in wrapper
    return func(*args, session=session, **kwargs)
           ^^^^^^^^^^^^^^^^^^^^^^^^^^^^^^^^^^^^^^
  File "/Users/user/Documents/learningProg/dataengineering/de_dbt_snowflake_airflow/airflow-env/lib/python3.11/site-packages/airflow/models/taskinstance.py", line 3006, in _run_raw_task
    return _run_raw_task(
           ^^^^^^^^^^^^^^
  File "/Users/user/Documents/learningProg/dataengineering/de_dbt_snowflake_airflow/airflow-env/lib/python3.11/site-packages/airflow/models/taskinstance.py", line 274, in _run_raw_task
    TaskInstance._execute_task_with_callbacks(
  File "/Users/user/Documents/learningProg/dataengineering/de_dbt_snowflake_airflow/airflow-env/lib/python3.11/site-packages/airflow/models/taskinstance.py", line 3161, in _execute_task_with_callbacks
    result = self._execute_task(context, task_orig)
             ^^^^^^^^^^^^^^^^^^^^^^^^^^^^^^^^^^^^^^
  File "/Users/user/Documents/learningProg/dataengineering/de_dbt_snowflake_airflow/airflow-env/lib/python3.11/site-packages/airflow/models/taskinstance.py", line 3185, in _execute_task
    return _execute_task(self, context, task_orig)
           ^^^^^^^^^^^^^^^^^^^^^^^^^^^^^^^^^^^^^^^
  File "/Users/user/Documents/learningProg/dataengineering/de_dbt_snowflake_airflow/airflow-env/lib/python3.11/site-packages/airflow/models/taskinstance.py", line 768, in _execute_task
    result = _execute_callable(context=context, **execute_callable_kwargs)
             ^^^^^^^^^^^^^^^^^^^^^^^^^^^^^^^^^^^^^^^^^^^^^^^^^^^^^^^^^^^^^
  File "/Users/user/Documents/learningProg/dataengineering/de_dbt_snowflake_airflow/airflow-env/lib/python3.11/site-packages/airflow/models/taskinstance.py", line 734, in _execute_callable
    return ExecutionCallableRunner(
           ^^^^^^^^^^^^^^^^^^^^^^^^
  File "/Users/user/Documents/learningProg/dataengineering/de_dbt_snowflake_airflow/airflow-env/lib/python3.11/site-packages/airflow/utils/operator_helpers.py", line 252, in run
    return self.func(*args, **kwargs)
           ^^^^^^^^^^^^^^^^^^^^^^^^^^
  File "/Users/user/Documents/learningProg/dataengineering/de_dbt_snowflake_airflow/airflow-env/lib/python3.11/site-packages/airflow/models/baseoperator.py", line 424, in wrapper
    return func(self, *args, **kwargs)
           ^^^^^^^^^^^^^^^^^^^^^^^^^^^
  File "/Users/user/Documents/learningProg/dataengineering/de_dbt_snowflake_airflow/airflow-env/lib/python3.11/site-packages/airflow/operators/bash.py", line 276, in execute
    raise AirflowException(
airflow.exceptions.AirflowException: Bash command failed. The command returned a non-zero exit code 1.
[2025-04-15T17:32:04.174+0200] {local_task_job_runner.py:266} INFO - Task exited with return code 1
[2025-04-15T17:32:04.212+0200] {taskinstance.py:3901} INFO - 0 downstream tasks scheduled from follow-on schedule check
[2025-04-15T17:32:04.213+0200] {local_task_job_runner.py:245} INFO - ::endgroup::
