[2025-04-15T17:27:44.853+0200] {local_task_job_runner.py:123} INFO - ::group::Pre task execution logs
[2025-04-15T17:27:44.868+0200] {taskinstance.py:2614} INFO - Dependencies all met for dep_context=non-requeueable deps ti=<TaskInstance: dbt_snowflake_pipeline.dbt_tasks.dbt_debug manual__2025-04-15T15:27:38.487435+00:00 [queued]>
[2025-04-15T17:27:44.877+0200] {taskinstance.py:2614} INFO - Dependencies all met for dep_context=requeueable deps ti=<TaskInstance: dbt_snowflake_pipeline.dbt_tasks.dbt_debug manual__2025-04-15T15:27:38.487435+00:00 [queued]>
[2025-04-15T17:27:44.877+0200] {taskinstance.py:2867} INFO - Starting attempt 1 of 2
[2025-04-15T17:27:44.889+0200] {taskinstance.py:2890} INFO - Executing <Task(BashOperator): dbt_tasks.dbt_debug> on 2025-04-15 15:27:38.487435+00:00
[2025-04-15T17:27:44.895+0200] {standard_task_runner.py:72} INFO - Started process 56774 to run task
[2025-04-15T17:27:44.903+0200] {standard_task_runner.py:104} INFO - Running: ['airflow', 'tasks', 'run', 'dbt_snowflake_pipeline', 'dbt_tasks.dbt_debug', 'manual__2025-04-15T15:27:38.487435+00:00', '--job-id', '18', '--raw', '--subdir', 'DAGS_FOLDER/dbt_snowflke_airflow.py', '--cfg-path', '/var/folders/gn/cr4yj18d1tv34pkws9v_kq1r0000gn/T/tmpvsybjcrw']
[2025-04-15T17:27:44.906+0200] {standard_task_runner.py:105} INFO - Job 18: Subtask dbt_tasks.dbt_debug
[2025-04-15T17:27:44.960+0200] {task_command.py:467} INFO - Running <TaskInstance: dbt_snowflake_pipeline.dbt_tasks.dbt_debug manual__2025-04-15T15:27:38.487435+00:00 [running]> on host macbook-pro-de-user.local
[2025-04-15T17:27:45.027+0200] {taskinstance.py:3134} INFO - Exporting env vars: AIRFLOW_CTX_DAG_OWNER='airflow' AIRFLOW_CTX_DAG_ID='dbt_snowflake_pipeline' AIRFLOW_CTX_TASK_ID='dbt_tasks.dbt_debug' AIRFLOW_CTX_EXECUTION_DATE='2025-04-15T15:27:38.487435+00:00' AIRFLOW_CTX_TRY_NUMBER='1' AIRFLOW_CTX_DAG_RUN_ID='manual__2025-04-15T15:27:38.487435+00:00'
[2025-04-15T17:27:45.029+0200] {logging_mixin.py:190} INFO - Task instance is in running state
[2025-04-15T17:27:45.030+0200] {logging_mixin.py:190} INFO -  Previous state of the Task instance: queued
[2025-04-15T17:27:45.030+0200] {logging_mixin.py:190} INFO - Current task name:dbt_tasks.dbt_debug state:running start_date:2025-04-15 15:27:44.868673+00:00
[2025-04-15T17:27:45.031+0200] {logging_mixin.py:190} INFO - Dag name:dbt_snowflake_pipeline and current dag run status:running
[2025-04-15T17:27:45.032+0200] {taskinstance.py:732} INFO - ::endgroup::
[2025-04-15T17:27:45.033+0200] {subprocess.py:78} INFO - Tmp dir root location: /var/folders/gn/cr4yj18d1tv34pkws9v_kq1r0000gn/T
[2025-04-15T17:27:45.034+0200] {subprocess.py:88} INFO - Running command: ['/bin/bash', '-c', 'dbt debug --profiles-dir ~/.dbt/profiles.yml --project-dir /Users/user/Documents/learningProg/dataengineering/de_dbt_snowflake_airflow/snowflake']
[2025-04-15T17:27:45.043+0200] {subprocess.py:99} INFO - Output:
[2025-04-15T17:27:47.814+0200] {subprocess.py:106} INFO - [0m15:27:47  Running with dbt=1.9.4
[2025-04-15T17:27:47.844+0200] {subprocess.py:106} INFO - [0m15:27:47  dbt version: 1.9.4
[2025-04-15T17:27:47.845+0200] {subprocess.py:106} INFO - [0m15:27:47  python version: 3.11.11
[2025-04-15T17:27:47.846+0200] {subprocess.py:106} INFO - [0m15:27:47  python path: /Users/user/Documents/learningProg/dataengineering/de_dbt_snowflake_airflow/airflow-env/bin/python
[2025-04-15T17:27:47.848+0200] {subprocess.py:106} INFO - [0m15:27:47  os info: macOS-15.3.2-x86_64-i386-64bit
[2025-04-15T17:27:47.849+0200] {subprocess.py:106} INFO - [0m15:27:47  Using profiles dir at /Users/user/.dbt/profiles.yml
[2025-04-15T17:27:47.850+0200] {subprocess.py:106} INFO - [0m15:27:47  Using profiles.yml file at /Users/user/.dbt/profiles.yml/profiles.yml
[2025-04-15T17:27:47.851+0200] {subprocess.py:106} INFO - [0m15:27:47  Using dbt_project.yml file at /Users/user/Documents/learningProg/dataengineering/de_dbt_snowflake_airflow/snowflake/dbt_project.yml
[2025-04-15T17:27:48.011+0200] {subprocess.py:106} INFO - [0m15:27:48  Configuration:
[2025-04-15T17:27:48.012+0200] {subprocess.py:106} INFO - [0m15:27:48    profiles.yml file [[31mERROR not found[0m]
[2025-04-15T17:27:48.013+0200] {subprocess.py:106} INFO - [0m15:27:48    dbt_project.yml file [[32mOK found and valid[0m]
[2025-04-15T17:27:48.014+0200] {subprocess.py:106} INFO - [0m15:27:48  Required dependencies:
[2025-04-15T17:27:48.059+0200] {subprocess.py:106} INFO - [0m15:27:48   - git [[32mOK found[0m]
[2025-04-15T17:27:48.060+0200] {subprocess.py:106} INFO - 
[2025-04-15T17:27:48.060+0200] {subprocess.py:106} INFO - [0m15:27:48  Connection test skipped since no profile was found
[2025-04-15T17:27:48.061+0200] {subprocess.py:106} INFO - [0m15:27:48  [31m1 check failed:[0m
[2025-04-15T17:27:48.062+0200] {subprocess.py:106} INFO - [0m15:27:48  dbt looked for a profiles.yml file in /Users/user/.dbt/profiles.yml/profiles.yml, but did
[2025-04-15T17:27:48.062+0200] {subprocess.py:106} INFO - not find one. For more information on configuring your profile, consult the
[2025-04-15T17:27:48.063+0200] {subprocess.py:106} INFO - documentation:
[2025-04-15T17:27:48.064+0200] {subprocess.py:106} INFO - 
[2025-04-15T17:27:48.064+0200] {subprocess.py:106} INFO - https://docs.getdbt.com/docs/configure-your-profile
[2025-04-15T17:27:48.065+0200] {subprocess.py:106} INFO - 
[2025-04-15T17:27:48.065+0200] {subprocess.py:106} INFO - 
[2025-04-15T17:27:48.702+0200] {subprocess.py:110} INFO - Command exited with return code 1
[2025-04-15T17:27:48.717+0200] {taskinstance.py:3313} ERROR - Task failed with exception
Traceback (most recent call last):
  File "/Users/user/Documents/learningProg/dataengineering/de_dbt_snowflake_airflow/airflow-env/lib/python3.11/site-packages/airflow/models/taskinstance.py", line 768, in _execute_task
    result = _execute_callable(context=context, **execute_callable_kwargs)
             ^^^^^^^^^^^^^^^^^^^^^^^^^^^^^^^^^^^^^^^^^^^^^^^^^^^^^^^^^^^^^
  File "/Users/user/Documents/learningProg/dataengineering/de_dbt_snowflake_airflow/airflow-env/lib/python3.11/site-packages/airflow/models/taskinstance.py", line 734, in _execute_callable
    return ExecutionCallableRunner(
           ^^^^^^^^^^^^^^^^^^^^^^^^
  File "/Users/user/Documents/learningProg/dataengineering/de_dbt_snowflake_airflow/airflow-env/lib/python3.11/site-packages/airflow/utils/operator_helpers.py", line 252, in run
    return self.func(*args, **kwargs)
           ^^^^^^^^^^^^^^^^^^^^^^^^^^
  File "/Users/user/Documents/learningProg/dataengineering/de_dbt_snowflake_airflow/airflow-env/lib/python3.11/site-packages/airflow/models/baseoperator.py", line 424, in wrapper
    return func(self, *args, **kwargs)
           ^^^^^^^^^^^^^^^^^^^^^^^^^^^
  File "/Users/user/Documents/learningProg/dataengineering/de_dbt_snowflake_airflow/airflow-env/lib/python3.11/site-packages/airflow/operators/bash.py", line 276, in execute
    raise AirflowException(
airflow.exceptions.AirflowException: Bash command failed. The command returned a non-zero exit code 1.
[2025-04-15T17:27:48.732+0200] {logging_mixin.py:190} INFO - Task instance in failure state
[2025-04-15T17:27:48.733+0200] {logging_mixin.py:190} INFO - Task start:2025-04-15 15:27:44.868673+00:00 end:2025-04-15 15:27:48.731806+00:00 duration:3.863133
[2025-04-15T17:27:48.734+0200] {logging_mixin.py:190} INFO - Task:<Task(BashOperator): dbt_tasks.dbt_debug> dag:<DAG: dbt_snowflake_pipeline> dagrun:<DagRun dbt_snowflake_pipeline @ 2025-04-15 15:27:38.487435+00:00: manual__2025-04-15T15:27:38.487435+00:00, state:running, queued_at: 2025-04-15 15:27:38.549381+00:00. externally triggered: True>
[2025-04-15T17:27:48.735+0200] {logging_mixin.py:190} INFO - Failure caused by Bash command failed. The command returned a non-zero exit code 1.
[2025-04-15T17:27:48.736+0200] {taskinstance.py:1226} INFO - Marking task as UP_FOR_RETRY. dag_id=dbt_snowflake_pipeline, task_id=dbt_tasks.dbt_debug, run_id=manual__2025-04-15T15:27:38.487435+00:00, execution_date=20250415T152738, start_date=20250415T152744, end_date=20250415T152748
[2025-04-15T17:27:48.766+0200] {taskinstance.py:341} INFO - ::group::Post task execution logs
[2025-04-15T17:27:48.767+0200] {standard_task_runner.py:124} ERROR - Failed to execute job 18 for task dbt_tasks.dbt_debug (Bash command failed. The command returned a non-zero exit code 1.; 56774)
Traceback (most recent call last):
  File "/Users/user/Documents/learningProg/dataengineering/de_dbt_snowflake_airflow/airflow-env/lib/python3.11/site-packages/airflow/task/task_runner/standard_task_runner.py", line 117, in _start_by_fork
    ret = args.func(args, dag=self.dag)
          ^^^^^^^^^^^^^^^^^^^^^^^^^^^^^
  File "/Users/user/Documents/learningProg/dataengineering/de_dbt_snowflake_airflow/airflow-env/lib/python3.11/site-packages/airflow/cli/cli_config.py", line 49, in command
    return func(*args, **kwargs)
           ^^^^^^^^^^^^^^^^^^^^^
  File "/Users/user/Documents/learningProg/dataengineering/de_dbt_snowflake_airflow/airflow-env/lib/python3.11/site-packages/airflow/utils/cli.py", line 116, in wrapper
    return f(*args, **kwargs)
           ^^^^^^^^^^^^^^^^^^
  File "/Users/user/Documents/learningProg/dataengineering/de_dbt_snowflake_airflow/airflow-env/lib/python3.11/site-packages/airflow/cli/commands/task_command.py", line 483, in task_run
    task_return_code = _run_task_by_selected_method(args, _dag, ti)
                       ^^^^^^^^^^^^^^^^^^^^^^^^^^^^^^^^^^^^^^^^^^^^
  File "/Users/user/Documents/learningProg/dataengineering/de_dbt_snowflake_airflow/airflow-env/lib/python3.11/site-packages/airflow/cli/commands/task_command.py", line 256, in _run_task_by_selected_method
    return _run_raw_task(args, ti)
           ^^^^^^^^^^^^^^^^^^^^^^^
  File "/Users/user/Documents/learningProg/dataengineering/de_dbt_snowflake_airflow/airflow-env/lib/python3.11/site-packages/airflow/cli/commands/task_command.py", line 341, in _run_raw_task
    return ti._run_raw_task(
           ^^^^^^^^^^^^^^^^^
  File "/Users/user/Documents/learningProg/dataengineering/de_dbt_snowflake_airflow/airflow-env/lib/python3.11/site-packages/airflow/utils/session.py", line 97, in wrapper
    return func(*args, session=session, **kwargs)
           ^^^^^^^^^^^^^^^^^^^^^^^^^^^^^^^^^^^^^^
  File "/Users/user/Documents/learningProg/dataengineering/de_dbt_snowflake_airflow/airflow-env/lib/python3.11/site-packages/airflow/models/taskinstance.py", line 3006, in _run_raw_task
    return _run_raw_task(
           ^^^^^^^^^^^^^^
  File "/Users/user/Documents/learningProg/dataengineering/de_dbt_snowflake_airflow/airflow-env/lib/python3.11/site-packages/airflow/models/taskinstance.py", line 274, in _run_raw_task
    TaskInstance._execute_task_with_callbacks(
  File "/Users/user/Documents/learningProg/dataengineering/de_dbt_snowflake_airflow/airflow-env/lib/python3.11/site-packages/airflow/models/taskinstance.py", line 3161, in _execute_task_with_callbacks
    result = self._execute_task(context, task_orig)
             ^^^^^^^^^^^^^^^^^^^^^^^^^^^^^^^^^^^^^^
  File "/Users/user/Documents/learningProg/dataengineering/de_dbt_snowflake_airflow/airflow-env/lib/python3.11/site-packages/airflow/models/taskinstance.py", line 3185, in _execute_task
    return _execute_task(self, context, task_orig)
           ^^^^^^^^^^^^^^^^^^^^^^^^^^^^^^^^^^^^^^^
  File "/Users/user/Documents/learningProg/dataengineering/de_dbt_snowflake_airflow/airflow-env/lib/python3.11/site-packages/airflow/models/taskinstance.py", line 768, in _execute_task
    result = _execute_callable(context=context, **execute_callable_kwargs)
             ^^^^^^^^^^^^^^^^^^^^^^^^^^^^^^^^^^^^^^^^^^^^^^^^^^^^^^^^^^^^^
  File "/Users/user/Documents/learningProg/dataengineering/de_dbt_snowflake_airflow/airflow-env/lib/python3.11/site-packages/airflow/models/taskinstance.py", line 734, in _execute_callable
    return ExecutionCallableRunner(
           ^^^^^^^^^^^^^^^^^^^^^^^^
  File "/Users/user/Documents/learningProg/dataengineering/de_dbt_snowflake_airflow/airflow-env/lib/python3.11/site-packages/airflow/utils/operator_helpers.py", line 252, in run
    return self.func(*args, **kwargs)
           ^^^^^^^^^^^^^^^^^^^^^^^^^^
  File "/Users/user/Documents/learningProg/dataengineering/de_dbt_snowflake_airflow/airflow-env/lib/python3.11/site-packages/airflow/models/baseoperator.py", line 424, in wrapper
    return func(self, *args, **kwargs)
           ^^^^^^^^^^^^^^^^^^^^^^^^^^^
  File "/Users/user/Documents/learningProg/dataengineering/de_dbt_snowflake_airflow/airflow-env/lib/python3.11/site-packages/airflow/operators/bash.py", line 276, in execute
    raise AirflowException(
airflow.exceptions.AirflowException: Bash command failed. The command returned a non-zero exit code 1.
[2025-04-15T17:27:48.783+0200] {local_task_job_runner.py:266} INFO - Task exited with return code 1
[2025-04-15T17:27:48.806+0200] {taskinstance.py:3901} INFO - 0 downstream tasks scheduled from follow-on schedule check
[2025-04-15T17:27:48.807+0200] {local_task_job_runner.py:245} INFO - ::endgroup::
